Workbook

Sheet Traceability Matrix
A1: REQUIREMENTS TRACEABILITY MATRIX (RTM)
A2: Project / Application: | B2: <enter project name> | D2: Document Version: | E2: 1.0 | G2: Date: | H2: <dd-mmm-yyyy>
A3: Module / Release: | B3: <enter module or release> | D3: Prepared By: | E3: <name> | G3: Review Status: | H3: Draft
A5: Test Case ID | B5: Test Case Description | C5: Test Type | D5: Execution Status | E5: # Reqs Covered | F5: REQ-001 | G5: REQ-002 | H5: REQ-003 | I5: REQ-004 | J5: REQ-005 | K5: REQ-006 | L5: REQ-007 | M5: REQ-008 | N5: REQ-009 | O5: REQ-010 | P5: REQ-011 | Q5: REQ-012
A6: Requirement Description (auto-filled from the Requirements sheet) → | F6: =IFERROR(INDEX(Requirements!$B$6:$B$105,MATCH(F$5,Requirements!$A$6:$A$105,0)),"") -> The system shall authenticate a registered user with a valid username and password. | G6: =IFERROR(INDEX(Requirements!$B$6:$B$105,MATCH(G$5,Requirements!$A$6:$A$105,0)),"") -> The system shall lock an account after five consecutive failed login attempts. | H6: =IFERROR(INDEX(Requirements!$B$6:$B$105,MATCH(H$5,Requirements!$A$6:$A$105,0)),"") -> The system shall enforce multi-factor authentication for access from an unrecognised device. | I6: =IFERROR(INDEX(Requirements!$B$6:$B$105,MATCH(I$5,Requirements!$A$6:$A$105,0)),"") -> The dashboard shall render within three seconds under a load of 500 concurrent users. | J6: =IFERROR(INDEX(Requirements!$B$6:$B$105,MATCH(J$5,Requirements!$A$6:$A$105,0)),"") -> 0 | K6: =IFERROR(INDEX(Requirements!$B$6:$B$105,MATCH(K$5,Requirements!$A$6:$A$105,0)),"") -> 0 | L6: =IFERROR(INDEX(Requirements!$B$6:$B$105,MATCH(L$5,Requirements!$A$6:$A$105,0)),"") -> 0 | M6: =IFERROR(INDEX(Requirements!$B$6:$B$105,MATCH(M$5,Requirements!$A$6:$A$105,0)),"") -> 0 | ... Q6: =IFERROR(INDEX(Requirements!$B$6:$B$105,MATCH(Q$5,Requirements!$A$6:$A$105,0)),"") -> 0
A7: TC-001 | B7: Valid user logs in with correct credentials | C7: Functional | D7: Pass | E7: =IF($A7="","",COUNTIF(F7:Q7,"x")) -> 1 | F7: X
A8: TC-002 | B8: Login rejected after 5 invalid attempts | C8: Negative | D8: Pass | E8: =IF($A8="","",COUNTIF(F8:Q8,"x")) -> 1 | G8: X
A9: TC-003 | B9: MFA challenge is enforced on new device | C9: Security | D9: Fail | E9: =IF($A9="","",COUNTIF(F9:Q9,"x")) -> 2 | G9: X | H9: X
A10: TC-004 | B10: Password reset link expires after 15 minutes | C10: Functional | D10: Blocked | E10: =IF($A10="","",COUNTIF(F10:Q10,"x")) -> 1 | H10: X
A11: TC-005 | B11: Dashboard loads within 3 seconds at 500 users | C11: Performance | D11: Not Run | E11: =IF($A11="","",COUNTIF(F11:Q11,"x")) -> 1 | I11: X
A12: TC-006 | E12: =IF($A12="","",COUNTIF(F12:Q12,"x")) -> 0
A13: TC-007 | E13: =IF($A13="","",COUNTIF(F13:Q13,"x")) -> 0
A14: TC-008 | E14: =IF($A14="","",COUNTIF(F14:Q14,"x")) -> 0
A15: TC-009 | E15: =IF($A15="","",COUNTIF(F15:Q15,"x")) -> 0
A16: TC-010 | E16: =IF($A16="","",COUNTIF(F16:Q16,"x")) -> 0
A17: TC-011 | E17: =IF($A17="","",COUNTIF(F17:Q17,"x")) -> 0
A18: TC-012 | E18: =IF($A18="","",COUNTIF(F18:Q18,"x")) -> 0
A19: TC-013 | E19: =IF($A19="","",COUNTIF(F19:Q19,"x")) -> 0
A20: TC-014 | E20: =IF($A20="","",COUNTIF(F20:Q20,"x")) -> 0
A21: TC-015 | E21: =IF($A21="","",COUNTIF(F21:Q21,"x")) -> 0
A22: TC-016 | E22: =IF($A22="","",COUNTIF(F22:Q22,"x")) -> 0
A23: TC-017 | E23: =IF($A23="","",COUNTIF(F23:Q23,"x")) -> 0
... A26: TC-020 | E26: =IF($A26="","",COUNTIF(F26:Q26,"x")) -> 0
A27: # Test Cases Covering → | F27: =COUNTIF(F7:F26,"x") -> 1 | G27: =COUNTIF(G7:G26,"x") -> 2 | H27: =COUNTIF(H7:H26,"x") -> 2 | I27: =COUNTIF(I7:I26,"x") -> 1 | J27: =COUNTIF(J7:J26,"x") -> 0 | K27: =COUNTIF(K7:K26,"x") -> 0 | L27: =COUNTIF(L7:L26,"x") -> 0 | M27: =COUNTIF(M7:M26,"x") -> 0 | ... Q27: =COUNTIF(Q7:Q26,"x") -> 0
A28: Coverage Status → | F28: =IF(F27>0,"Covered","GAP") -> Covered | G28: =IF(G27>0,"Covered","GAP") -> Covered | H28: =IF(H27>0,"Covered","GAP") -> Covered | I28: =IF(I27>0,"Covered","GAP") -> Covered | J28: =IF(J27>0,"Covered","GAP") -> GAP | K28: =IF(K27>0,"Covered","GAP") -> GAP | L28: =IF(L27>0,"Covered","GAP") -> GAP | M28: =IF(M27>0,"Covered","GAP") -> GAP | ... Q28: =IF(Q27>0,"Covered","GAP") -> GAP
A30: COVERAGE SUMMARY
A31: Total Requirements in Scope | E31: =COUNTA(Requirements!$A$6:$A$105) -> 12
A32: Requirements Covered | E32: =COUNTIF($F$28:$Q$28,"Covered") -> 4
A33: Requirements with No Coverage (GAP) | E33: =COUNTIF($F$28:$Q$28,"GAP") -> 8
A34: Requirement Coverage % | E34: =IFERROR($E$32/$E$31,0) -> 0.33333333
A35: Total Test Cases Mapped | E35: =COUNTIF($E$7:$E$26,">0") -> 5
A36: Test Cases Passed | E36: =COUNTIF($D$7:$D$26,"Pass") -> 2
A37: Test Cases Failed | E37: =COUNTIF($D$7:$D$26,"Fail") -> 1
A38: Test Execution Pass % | E38: =IFERROR($E$36/COUNTIF($D$7:$D$26,"<>"),0) -> 0.4
A40: HOW TO USE / LEGEND
A41: • Mark an "X" where a test case verifies the requirement in that column. One requirement may be covered by many test cases, and one test case may cover many requirements.
A42: • White cells are for your input. Grey cells are formulas (counts, coverage status, summary) - do not overwrite them.
A43: • Requirement IDs in row 5 and their descriptions in row 6 are driven by the Requirements sheet. Add or rename requirements there first.
A44: • A requirement with no "X" in its column is flagged GAP in red - every GAP must be closed or formally accepted before sign-off.
A45: • Rows TC-001 to TC-005 are illustrative sample data showing the expected format. Delete them before real use.
...

Sheet Requirements
A1: REQUIREMENT REGISTER
A2: Source of truth for requirement IDs and descriptions. The Traceability Matrix pulls row 5 headers against column A and descriptions from column B.
A5: Req ID | B5: Requirement Description | C5: Requirement Type | D5: Priority | E5: Source Document / Section | F5: Business Owner | G5: # Test Cases Mapped | H5: Coverage Status
A6: REQ-001 | B6: The system shall authenticate a registered user with a valid username and password. | C6: Functional | D6: High | E6: BRD v2.1 / Sec 4.1 | F6: Identity Team | G6: =IFERROR(HLOOKUP($A6,'Traceability Matrix'!$F$5:$Q$27,23,FALSE()),0) -> 1 | H6: =IF($A6="","",IF($G6>0,"Covered","GAP")) -> Covered
A7: REQ-002 | B7: The system shall lock an account after five consecutive failed login attempts. | C7: Security | D7: High | E7: BRD v2.1 / Sec 4.3 | F7: Security Team | G7: =IFERROR(HLOOKUP($A7,'Traceability Matrix'!$F$5:$Q$27,23,FALSE()),0) -> 2 | H7: =IF($A7="","",IF($G7>0,"Covered","GAP")) -> Covered
A8: REQ-003 | B8: The system shall enforce multi-factor authentication for access from an unrecognised device. | C8: Security | D8: Critical | E8: SRS v1.4 / Sec 2.2 | F8: Security Team | G8: =IFERROR(HLOOKUP($A8,'Traceability Matrix'!$F$5:$Q$27,23,FALSE()),0) -> 2 | H8: =IF($A8="","",IF($G8>0,"Covered","GAP")) -> Covered
A9: REQ-004 | B9: The dashboard shall render within three seconds under a load of 500 concurrent users. | C9: Non-Functional | D9: Medium | E9: SRS v1.4 / Sec 6.5 | F9: Platform Team | G9: =IFERROR(HLOOKUP($A9,'Traceability Matrix'!$F$5:$Q$27,23,FALSE()),0) -> 1 | H9: =IF($A9="","",IF($G9>0,"Covered","GAP")) -> Covered
A10: REQ-005 | G10: =IFERROR(HLOOKUP($A10,'Traceability Matrix'!$F$5:$Q$27,23,FALSE()),0) -> 0 | H10: =IF($A10="","",IF($G10>0,"Covered","GAP")) -> GAP
A11: REQ-006 | G11: =IFERROR(HLOOKUP($A11,'Traceability Matrix'!$F$5:$Q$27,23,FALSE()),0) -> 0 | H11: =IF($A11="","",IF($G11>0,"Covered","GAP")) -> GAP
A12: REQ-007 | G12: =IFERROR(HLOOKUP($A12,'Traceability Matrix'!$F$5:$Q$27,23,FALSE()),0) -> 0 | H12: =IF($A12="","",IF($G12>0,"Covered","GAP")) -> GAP
A13: REQ-008 | G13: =IFERROR(HLOOKUP($A13,'Traceability Matrix'!$F$5:$Q$27,23,FALSE()),0) -> 0 | H13: =IF($A13="","",IF($G13>0,"Covered","GAP")) -> GAP
A14: REQ-009 | G14: =IFERROR(HLOOKUP($A14,'Traceability Matrix'!$F$5:$Q$27,23,FALSE()),0) -> 0 | H14: =IF($A14="","",IF($G14>0,"Covered","GAP")) -> GAP
A15: REQ-010 | G15: =IFERROR(HLOOKUP($A15,'Traceability Matrix'!$F$5:$Q$27,23,FALSE()),0) -> 0 | H15: =IF($A15="","",IF($G15>0,"Covered","GAP")) -> GAP
A16: REQ-011 | G16: =IFERROR(HLOOKUP($A16,'Traceability Matrix'!$F$5:$Q$27,23,FALSE()),0) -> 0 | H16: =IF($A16="","",IF($G16>0,"Covered","GAP")) -> GAP
A17: REQ-012 | G17: =IFERROR(HLOOKUP($A17,'Traceability Matrix'!$F$5:$Q$27,23,FALSE()),0) -> 0 | H17: =IF($A17="","",IF($G17>0,"Covered","GAP")) -> GAP
B19: Note: to add a requirement, fill the next free row here, then add a matching column header on the Traceability Matrix sheet using the same Req ID.

Sheet Test Cases
A1: TEST CASE REGISTER
A2: Detail behind each test case ID used in the matrix. Column H counts how many requirements the case is mapped to.
A5: Test Case ID | B5: Test Case Description | C5: Test Type | D5: Pre-conditions | E5: Expected Result | F5: Execution Status | G5: Tested By | H5: # Reqs Mapped | I5: Defect ID
A6: TC-001 | B6: Valid user logs in with correct credentials | C6: Functional | D6: Active account exists in the directory | E6: User is signed in and routed to the dashboard | F6: Pass | G6: <tester> | H6: =IFERROR(INDEX('Traceability Matrix'!$E$7:$E$26,MATCH($A6,'Traceability Matrix'!$A$7:$A$26,0)),0) -> 1
A7: TC-002 | B7: Login rejected after 5 invalid attempts | C7: Negative | D7: Active account; lockout policy enabled | E7: Account is locked and a notification is sent | F7: Pass | G7: <tester> | H7: =IFERROR(INDEX('Traceability Matrix'!$E$7:$E$26,MATCH($A7,'Traceability Matrix'!$A$7:$A$26,0)),0) -> 1
A8: TC-003 | B8: MFA challenge is enforced on new device | C8: Security | D8: User signs in from an unrecognised device | E8: MFA prompt is shown before access is granted | F8: Fail | G8: <tester> | H8: =IFERROR(INDEX('Traceability Matrix'!$E$7:$E$26,MATCH($A8,'Traceability Matrix'!$A$7:$A$26,0)),0) -> 2 | I8: DEF-1021
A9: TC-004 | B9: Password reset link expires after 15 minutes | C9: Functional | D9: Reset link generated 16 minutes earlier | E9: Link is rejected with an expiry message | F9: Blocked | G9: <tester> | H9: =IFERROR(INDEX('Traceability Matrix'!$E$7:$E$26,MATCH($A9,'Traceability Matrix'!$A$7:$A$26,0)),0) -> 1 | I9: DEF-1043
A10: TC-005 | B10: Dashboard loads within 3 seconds at 500 users | C10: Performance | D10: Load test harness configured for 500 users | E10: 95th percentile load time is under 3 seconds | F10: Not Run | G10: <tester> | H10: =IFERROR(INDEX('Traceability Matrix'!$E$7:$E$26,MATCH($A10,'Traceability Matrix'!$A$7:$A$26,0)),0) -> 1
A11: TC-006 | H11: =IFERROR(INDEX('Traceability Matrix'!$E$7:$E$26,MATCH($A11,'Traceability Matrix'!$A$7:$A$26,0)),0) -> 0
A12: TC-007 | H12: =IFERROR(INDEX('Traceability Matrix'!$E$7:$E$26,MATCH($A12,'Traceability Matrix'!$A$7:$A$26,0)),0) -> 0
A13: TC-008 | H13: =IFERROR(INDEX('Traceability Matrix'!$E$7:$E$26,MATCH($A13,'Traceability Matrix'!$A$7:$A$26,0)),0) -> 0
A14: TC-009 | H14: =IFERROR(INDEX('Traceability Matrix'!$E$7:$E$26,MATCH($A14,'Traceability Matrix'!$A$7:$A$26,0)),0) -> 0
A15: TC-010 | H15: =IFERROR(INDEX('Traceability Matrix'!$E$7:$E$26,MATCH($A15,'Traceability Matrix'!$A$7:$A$26,0)),0) -> 0
A16: TC-011 | H16: =IFERROR(INDEX('Traceability Matrix'!$E$7:$E$26,MATCH($A16,'Traceability Matrix'!$A$7:$A$26,0)),0) -> 0
A17: TC-012 | H17: =IFERROR(INDEX('Traceability Matrix'!$E$7:$E$26,MATCH($A17,'Traceability Matrix'!$A$7:$A$26,0)),0) -> 0
A18: TC-013 | H18: =IFERROR(INDEX('Traceability Matrix'!$E$7:$E$26,MATCH($A18,'Traceability Matrix'!$A$7:$A$26,0)),0) -> 0
A19: TC-014 | H19: =IFERROR(INDEX('Traceability Matrix'!$E$7:$E$26,MATCH($A19,'Traceability Matrix'!$A$7:$A$26,0)),0) -> 0
A20: TC-015 | H20: =IFERROR(INDEX('Traceability Matrix'!$E$7:$E$26,MATCH($A20,'Traceability Matrix'!$A$7:$A$26,0)),0) -> 0
A21: TC-016 | H21: =IFERROR(INDEX('Traceability Matrix'!$E$7:$E$26,MATCH($A21,'Traceability Matrix'!$A$7:$A$26,0)),0) -> 0
A22: TC-017 | H22: =IFERROR(INDEX('Traceability Matrix'!$E$7:$E$26,MATCH($A22,'Traceability Matrix'!$A$7:$A$26,0)),0) -> 0
... A25: TC-020 | H25: =IFERROR(INDEX('Traceability Matrix'!$E$7:$E$26,MATCH($A25,'Traceability Matrix'!$A$7:$A$26,0)),0) -> 0
B27: Note: rows TC-001 to TC-005 are sample data illustrating the expected format. A red 0 in '# Reqs Mapped' means the test case traces to no requirement.
